{
  "created": 1615998255.1555283,
  "duration": 0.0805823802947998,
  "exitcode": 2,
  "root": "/home/kevin/.scripts/test_wrappers",
  "environment": {
    "Python": "3.8.5",
    "Platform": "Linux-5.8.0-45-generic-x86_64-with-glibc2.29",
    "Packages": { "pytest": "6.2.2", "py": "1.10.0", "pluggy": "0.13.1" },
    "Plugins": {
      "cov": "2.11.1",
      "testmon": "1.0.3",
      "json-report": "1.2.4",
      "metadata": "1.11.0",
      "forked": "1.3.0",
      "django": "4.1.0",
      "xdist": "2.2.1",
      "Faker": "6.1.1"
    }
  },
  "summary": { "total": 0, "collected": 0 },
  "collectors": [
    {
      "nodeid": "",
      "outcome": "passed",
      "result": [
        { "nodeid": "src/__init__.py", "type": "Package" },
        { "nodeid": "src/common/__init__.py", "type": "Package" },
        { "nodeid": "src/pytest/__init__.py", "type": "Package" }
      ]
    },
    { "nodeid": "src/__init__.py", "outcome": "passed", "result": [] },
    { "nodeid": "src/common/__init__.py", "outcome": "passed", "result": [] },
    {
      "nodeid": "src/pytest/test_pytest.py",
      "outcome": "failed",
      "result": [],
      "longrepr": "src/pytest/test_pytest.py:1: in <module>\n    importerror\nE   NameError: name 'importerror' is not defined"
    },
    {
      "nodeid": "src/pytest/__init__.py",
      "outcome": "passed",
      "result": [{ "nodeid": "src/pytest/test_pytest.py", "type": "Module" }]
    }
  ],
  "tests": []
}
